Workbook

Sheet Start Here
B2: DSA Master Revision Sheet - v4
B3: Built for Kartik | C++ / STL | placement + internship prep
B5: The one rule | C5: Only the Master tab is editable (plus the yellow cells on Plan and Dashboard). Everything else calculates itself.
C6: You fill in: Status, Confidence, Attempts, Last Revised, Notes. Nothing else.
B8: Tier - read this first | C8: 922 questions is not a plan, it is a wall. The Tier column splits them into three tracks, and the Step column orders them: work down it, and see Path Stages for the ranges.
C9: Core (373) - at least two problems per pattern, every pattern in the sheet. Finish this and you have touched every idea an interview can ask. This is your actual target.
C10: Depth - extra reps on patterns you are still shaky on. Do these per topic, only where Pattern Radar says Weak.
C11: Stretch - Hard problems and Advanced DS (segment tree, Fenwick, sweep line, sparse table). Not placement-critical. Leave them until Core is above 80%.
C12: Tier is a dropdown, so you can promote or demote anything. If a Depth problem turns out to be the one that taught you the pattern, mark it Core.
B14: Status values (dropdown) | C14: Not Started - haven't opened it yet.
C15: Attempted - tried, could not finish. Auto-flagged DUE until you clear it.
C16: Solved - solved it, but needed a hint or the editorial.
C17: Mastered - solved clean, from scratch, and can re-derive the approach out loud.
C18: Revisit - solved once, but it faded. Also auto-flagged DUE.
C19: Done = Solved + Mastered everywhere in this workbook.
B21: Confidence (1-5 dropdown) - now it actually does something | C21: 1 = no idea why it works. 3 = can code it with effort. 5 = can explain the invariant and the complexity without thinking.
C22: Confidence drives the revision gap: 1 -> 2 days, 2 -> 4, 3 -> 7, 4 -> 21, 5 -> 45. Change those gaps on the Dashboard if they don't suit you.
C23: Be harsh. Inflated confidence just means the sheet stops showing you the thing you can't do.
B25: How revision works now | C25: Set Last Revised when you solve or re-solve something. Next Revision fills in by itself from your Confidence.
C26: The Due? column says DUE when that date arrives, or immediately if the status is Attempted or Revisit.
C27: Your daily routine: filter Due? = DUE on the Master tab. That is the whole revision decision. No judgement calls.
C28: Dashboard shows the live due count. If it climbs past about 15, stop taking new problems for a day and clear it.
B30: Pattern Radar - the honest tab | C30: Per-pattern totals, done count and average confidence across all 168 patterns.
C31: Verdict: Untouched (nothing solved), Weak (avg confidence 3 or below), Solid (above 3).
C32: Filter Verdict = Weak before an interview. That list is exactly what you will get caught on.
C33: Topic-level progress lies - 80% of Graphs done still means you have never written Dijkstra. Pattern level does not lie.
B35: Plan tab | C35: Enter a start date and a realistic problems-per-day number. It gives you six phase deadlines off the Core count.
C36: Order is not negotiable: Recursion and Backtracking come before DP, because DP is memoised recursion. Skipping that is why DP feels impossible.
B38: Weekly ritual (15 minutes, Sunday) | C38: 1. Pick 4 random Mastered problems, re-solve them timed. Anything that breaks drops to Revisit.
C39: 2. Open Pattern Radar, filter Weak, pick one pattern for the coming week.
C40: 3. Check Plan tab - are you ahead or behind? Adjust the pace cell, not the ambition.
B42: A note on the links | C42: LeetCode entries link straight to the problem. Non-LeetCode entries use a search link, because GFG problem IDs change over time and a hardcoded ID goes dead.
C43: When you open a search link and land on the right problem, paste the real URL over it. The sheet gets more accurate as you use it.
B45: Example row (delete once you start) | C45: Two Sum | Tier: Core | Status: Mastered | Confidence: 5 | Attempts: 2 | Last Revised: 2026-09-13 | Notes: hashmap of complement, one pass, O(n)

Sheet Path Stages
A1: Stage | B1: Steps | C1: Problems | D1: Easy | E1: Medium | F1: Hard | G1: Topics covered
A2: 1. Foundations - Core | B2: 1-87 | C2: 87 | D2: 52 | E2: 34 | F2: 1 | G2: Basics & Recursion, Arrays & Two Pointers, Sorting & Cyclic Sort, Hashing, Prefix Sum & Kadane, Sliding Window
A3: 1. Foundations - Depth | B3: 88-153 | C3: 66 | D3: 14 | E3: 51 | F3: 1 | G3: Arrays & Two Pointers, Sorting & Cyclic Sort, Hashing, Prefix Sum & Kadane, Sliding Window
A4: 1. Foundations - Stretch | B4: 154-163 | C4: 10 | D4: 0 | E4: 1 | F4: 9 | G4: Arrays & Two Pointers, Sorting & Cyclic Sort, Hashing, Prefix Sum & Kadane, Sliding Window
A5: 2. Search, Strings & Math - Core | B5: 164-257 | C5: 94 | D5: 63 | E5: 31 | F5: 0 | G5: Binary Search, Strings, Bit Manipulation, Math & Number Theory, Matrix / 2D
A6: 2. Search, Strings & Math - Depth | B6: 258-328 | C6: 71 | D6: 8 | E6: 58 | F6: 5 | G6: Binary Search, Strings, Bit Manipulation, Math & Number Theory, Matrix / 2D
A7: 2. Search, Strings & Math - Stretch | B7: 329-348 | C7: 20 | D7: 0 | E7: 0 | F7: 20 | G7: Binary Search, Strings, Bit Manipulation, Math & Number Theory
A8: 3. Linear DS - Core | B8: 349-394 | C8: 46 | D8: 20 | E8: 24 | F8: 2 | G8: Linked List, Stack & Queue, Heap & Priority Queue
A9: 3. Linear DS - Depth | B9: 395-443 | C9: 49 | D9: 1 | E9: 48 | F9: 0 | G9: Linked List, Stack & Queue, Heap & Priority Queue
A10: 3. Linear DS - Stretch | B10: 444-463 | C10: 20 | D10: 0 | E10: 0 | F10: 20 | G10: Linked List, Stack & Queue, Heap & Priority Queue
A11: 4. Greedy & Backtracking - Core | B11: 464-507 | C11: 44 | D11: 15 | E11: 29 | F11: 0 | G11: Intervals, Greedy, Backtracking
A12: 4. Greedy & Backtracking - Depth | B12: 508-552 | C12: 45 | D12: 0 | E12: 44 | F12: 1 | G12: Intervals, Greedy, Backtracking
A13: 4. Greedy & Backtracking - Stretch | B13: 553-577 | C13: 25 | D13: 0 | E13: 0 | F13: 25 | G13: Intervals, Greedy, Backtracking
... A19: 6. DP & Closers - Stretch | B19: 870-917 | C19: 48 | D19: 0 | E19: 0 | F19: 48 | G19: Dynamic Programming, Design, Advanced DS

Sheet Plan
B2: Phase Plan
B3: Fill the two yellow cells. Dates recalculate themselves. Core-track only - Depth and Stretch sit outside this timeline.
B5: Start date | C5: 2026-09-15 | D5: <- your realistic pace, not your ambitious one
B6: Core problems per day | C6: 2
B8: Phase | C8: Topics covered | D8: Core Qs | E8: Cumulative | F8: Days | G8: Target finish | H8: Done | I8: %
B9: Phase 1 - Foundations | C9: 01 - 05: Basics & Recursion, Arrays & Two Pointers, Sliding Window, Prefix Sum & Kadane, Sorting & Cyclic Sort | D9: =COUNTIFS(Master!$C$2:$C$918,"01. Basics & Recursion",Master!$G$2:$G$918,"Core")+COUNTIFS(Master!$C$2:$C$918,"02. Arrays & Two Pointers",Master!$G$2:$G$918,"Core")+COUNTIFS(Master!$C$2:$C$918,"03. Sliding Window",Master!$G$2:$G$918,"Core")+COUNTIFS(Master!$C$2:$C$918,"04. Prefix Sum & Kadane",Master!$G$2:$G$918,"Core")+COUNTIFS(Master!$C$2:$C$918,"05. Sorting & Cyclic Sort",Master!$G$2:$G$918,"Core") | E9: =$D9 | F9: =ROUNDUP($E9/$C$6,0) | G9: =$C$5+$F9 | H9: =COUNTIFS(Master!$C$2:$C$918,"01. Basics & Recursion",Master!$G$2:$G$918,"Core",Master!$J$2:$J$918,"Solved")+COUNTIFS(Master!$C$2:$C$918,"01. Basics & Recursion",Master!$G$2:$G$918,"Core",Master!$J$2:$J$918,"Mastered")+COUNTIFS(Master!$C$2:$C$918,"02. Arrays & Two Pointers",Master!$G$2:$G$918,"Core",Master!$J$2:$J$918,"Solved")+COUNTIFS(Master!$C$2:$C$918,"02. Arrays & Two Pointers",Master!$G$2:$G$918,"Core",Master!$J$2:$J$918,"Mastered")+COUNTIFS(Master!$C$2:$C$918,"03. Sliding Window",Master!$G$2:$G$918,"Core",Master!$J$2:$J$918,"Solved")+COUNTIFS(Master!$C$2:$C$918,"03. Sliding Window",Master!$G$2:$G$918,"Core",Master!$J$2:$J$918,"Mastered")+COUNTIFS(Master!$C$2:$C$918,"04. Prefix Sum & Kadane",Master!$G$2:$G$918,"Core",Master!$J$2:$J$918,"Solved")+COUNTIFS(Master!$C$2:$C$918,"04. Prefix Sum & Kadane",Master!$G$2:$G$918,"Core",Master!$J$2:$J$918,"Mastered")+COUNTIFS(Master!$C$2:$C$918,"05. Sorting & Cyclic Sort",Master!$G$2:$G$918,"Core",Master!$J$2:$J$918,"Solved")+COUNTIFS(Master!$C$2:$C$918,"05. Sorting & Cyclic Sort",Master!$G$2:$G$918,"Core",Master!$J$2:$J$918,"Mastered") | I9: =IFERROR($H9/$D9,0)
B10: Phase 2 - Search & Strings | C10: 06 - 09: Binary Search, Strings, Hashing, Matrix / 2D | D10: =COUNTIFS(Master!$C$2:$C$918,"06. Binary Search",Master!$G$2:$G$918,"Core")+COUNTIFS(Master!$C$2:$C$918,"07. Strings",Master!$G$2:$G$918,"Core")+COUNTIFS(Master!$C$2:$C$918,"08. Hashing",Master!$G$2:$G$918,"Core")+COUNTIFS(Master!$C$2:$C$918,"09. Matrix / 2D",Master!$G$2:$G$918,"Core") | E10: =$E9+$D10 | F10: =ROUNDUP($E10/$C$6,0) | G10: =$C$5+$F10 | H10: =COUNTIFS(Master!$C$2:$C$918,"06. Binary Search",Master!$G$2:$G$918,"Core",Master!$J$2:$J$918,"Solved")+COUNTIFS(Master!$C$2:$C$918,"06. Binary Search",Master!$G$2:$G$918,"Core",Master!$J$2:$J$918,"Mastered")+COUNTIFS(Master!$C$2:$C$918,"07. Strings",Master!$G$2:$G$918,"Core",Master!$J$2:$J$918,"Solved")+COUNTIFS(Master!$C$2:$C$918,"07. Strings",Master!$G$2:$G$918,"Core",Master!$J$2:$J$918,"Mastered")+COUNTIFS(Master!$C$2:$C$918,"08. Hashing",Master!$G$2:$G$918,"Core",Master!$J$2:$J$918,"Solved")+COUNTIFS(Master!$C$2:$C$918,"08. Hashing",Master!$G$2:$G$918,"Core",Master!$J$2:$J$918,"Mastered")+COUNTIFS(Master!$C$2:$C$918,"09. Matrix / 2D",Master!$G$2:$G$918,"Core",Master!$J$2:$J$918,"Solved")+COUNTIFS(Master!$C$2:$C$918,"09. Matrix / 2D",Master!$G$2:$G$918,"Core",Master!$J$2:$J$918,"Mastered") | I10: =IFERROR($H10/$D10,0)
B11: Phase 3 - Linear DS | C11: 10 - 12: Linked List, Stack & Queue, Heap & Priority Queue | D11: =COUNTIFS(Master!$C$2:$C$918,"10. Linked List",Master!$G$2:$G$918,"Core")+COUNTIFS(Master!$C$2:$C$918,"11. Stack & Queue",Master!$G$2:$G$918,"Core")+COUNTIFS(Master!$C$2:$C$918,"12. Heap & Priority Queue",Master!$G$2:$G$918,"Core") | E11: =$E10+$D11 | F11: =ROUNDUP($E11/$C$6,0) | G11: =$C$5+$F11 | H11: =COUNTIFS(Master!$C$2:$C$918,"10. Linked List",Master!$G$2:$G$918,"Core",Master!$J$2:$J$918,"Solved")+COUNTIFS(Master!$C$2:$C$918,"10. Linked List",Master!$G$2:$G$918,"Core",Master!$J$2:$J$918,"Mastered")+COUNTIFS(Master!$C$2:$C$918,"11. Stack & Queue",Master!$G$2:$G$918,"Core",Master!$J$2:$J$918,"Solved")+COUNTIFS(Master!$C$2:$C$918,"11. Stack & Queue",Master!$G$2:$G$918,"Core",Master!$J$2:$J$918,"Mastered")+COUNTIFS(Master!$C$2:$C$918,"12. Heap & Priority Queue",Master!$G$2:$G$918,"Core",Master!$J$2:$J$918,"Solved")+COUNTIFS(Master!$C$2:$C$918,"12. Heap & Priority Queue",Master!$G$2:$G$918,"Core",Master!$J$2:$J$918,"Mastered") | I11: =IFERROR($H11/$D11,0)
B12: Phase 4 - Greedy & Backtracking | C12: 13 - 14: Greedy, Backtracking | D12: =COUNTIFS(Master!$C$2:$C$918,"13. Greedy",Master!$G$2:$G$918,"Core")+COUNTIFS(Master!$C$2:$C$918,"14. Backtracking",Master!$G$2:$G$918,"Core") | E12: =$E11+$D12 | F12: =ROUNDUP($E12/$C$6,0) | G12: =$C$5+$F12 | H12: =COUNTIFS(Master!$C$2:$C$918,"13. Greedy",Master!$G$2:$G$918,"Core",Master!$J$2:$J$918,"Solved")+COUNTIFS(Master!$C$2:$C$918,"13. Greedy",Master!$G$2:$G$918,"Core",Master!$J$2:$J$918,"Mastered")+COUNTIFS(Master!$C$2:$C$918,"14. Backtracking",Master!$G$2:$G$918,"Core",Master!$J$2:$J$918,"Solved")+COUNTIFS(Master!$C$2:$C$918,"14. Backtracking",Master!$G$2:$G$918,"Core",Master!$J$2:$J$918,"Mastered") | I12: =IFERROR($H12/$D12,0)
B13: Phase 5 - Trees & Graphs | C13: 15 - 17: Trees & BST, Tries, Graphs | D13: =COUNTIFS(Master!$C$2:$C$918,"15. Trees & BST",Master!$G$2:$G$918,"Core")+COUNTIFS(Master!$C$2:$C$918,"16. Tries",Master!$G$2:$G$918,"Core")+COUNTIFS(Master!$C$2:$C$918,"17. Graphs",Master!$G$2:$G$918,"Core") | E13: =$E12+$D13 | F13: =ROUNDUP($E13/$C$6,0) | G13: =$C$5+$F13 | H13: =COUNTIFS(Master!$C$2:$C$918,"15. Trees & BST",Master!$G$2:$G$918,"Core",Master!$J$2:$J$918,"Solved")+COUNTIFS(Master!$C$2:$C$918,"15. Trees & BST",Master!$G$2:$G$918,"Core",Master!$J$2:$J$918,"Mastered")+COUNTIFS(Master!$C$2:$C$918,"16. Tries",Master!$G$2:$G$918,"Core",Master!$J$2:$J$918,"Solved")+COUNTIFS(Master!$C$2:$C$918,"16. Tries",Master!$G$2:$G$918,"Core",Master!$J$2:$J$918,"Mastered")+COUNTIFS(Master!$C$2:$C$918,"17. Graphs",Master!$G$2:$G$918,"Core",Master!$J$2:$J$918,"Solved")+COUNTIFS(Master!$C$2:$C$918,"17. Graphs",Master!$G$2:$G$918,"Core",Master!$J$2:$J$918,"Mastered") | I13: =IFERROR($H13/$D13,0)
B14: Phase 6 - DP & Closers | C14: 18 - 23: Dynamic Programming, Bit Manipulation, Math & Number Theory, Intervals, Design, Advanced DS | D14: =COUNTIFS(Master!$C$2:$C$918,"18. Dynamic Programming",Master!$G$2:$G$918,"Core")+COUNTIFS(Master!$C$2:$C$918,"19. Bit Manipulation",Master!$G$2:$G$918,"Core")+COUNTIFS(Master!$C$2:$C$918,"20. Math & Number Theory",Master!$G$2:$G$918,"Core")+COUNTIFS(Master!$C$2:$C$918,"21. Intervals",Master!$G$2:$G$918,"Core")+COUNTIFS(Master!$C$2:$C$918,"22. Design",Master!$G$2:$G$918,"Core")+COUNTIFS(Master!$C$2:$C$918,"23. Advanced DS",Master!$G$2:$G$918,"Core") | E14: =$E13+$D14 | F14: =ROUNDUP($E14/$C$6,0) | G14: =$C$5+$F14 | H14: =COUNTIFS(Master!$C$2:$C$918,"18. Dynamic Programming",Master!$G$2:$G$918,"Core",Master!$J$2:$J$918,"Solved")+COUNTIFS(Master!$C$2:$C$918,"18. Dynamic Programming",Master!$G$2:$G$918,"Core",Master!$J$2:$J$918,"Mastered")+COUNTIFS(Master!$C$2:$C$918,"19. Bit Manipulation",Master!$G$2:$G$918,"Core",Master!$J$2:$J$918,"Solved")+COUNTIFS(Master!$C$2:$C$918,"19. Bit Manipulation",Master!$G$2:$G$918,"Core",Master!$J$2:$J$918,"Mastered")+COUNTIFS(Master!$C$2:$C$918,"20. Math & Number Theory",Master!$G$2:$G$918,"Core",Master!$J$2:$J$918,"Solved")+COUNTIFS(Master!$C$2:$C$918,"20. Math & Number Theory",Master!$G$2:$G$918,"Core",Master!$J$2:$J$918,"Mastered")+COUNTIFS(Master!$C$2:$C$918,"21. Intervals",Master!$G$2:$G$918,"Core",Master!$J$2:$J$918,"Solved")+COUNTIFS(Master!$C$2:$C$918,"21. Intervals",Master!$G$2:$G$918,"Core",Master!$J$2:$J$918,"Mastered")+COUNTIFS(Master!$C$2:$C$918,"22. Design",Master!$G$2:$G$918,"Core",Master!$J$2:$J$918,"Solved")+COUNTIFS(Master!$C$2:$C$918,"22. Design",Master!$G$2:$G$918,"Core",Master!$J$2:$J$918,"Mastered")+COUNTIFS(Master!$C$2:$C$918,"23. Advanced DS",Master!$G$2:$G$918,"Core",Master!$J$2:$J$918,"Solved")+COUNTIFS(Master!$C$2:$C$918,"23. Advanced DS",Master!$G$2:$G$918,"Core",Master!$J$2:$J$918,"Mastered") | I14: =IFERROR($H14/$D14,0)
B15: TOTAL | D15: =SUM(D9:D14) | G15: =$G14 | H15: =SUM(H9:H14) | I15: =IFERROR($H15/$D15,0)
B17: Reality check
B18: - Days assume you solve every single day. You will not. Multiply the total by about 1.4 for a number you can trust.
B19: - Depth problems are for after the Core track is done, or for a topic you are actively interviewing on.
B20: - Stretch problems (Hard + Advanced DS) are not placement-critical. Ignore them until the Core track is above 80%.
B21: - If a phase slips by more than two weeks, cut Depth entirely rather than moving the target date again.

Sheet Master
A1: Step | B1: Stage | C1: Topic | D1: Pattern | E1: Problem | F1: Difficulty | G1: Tier | H1: Platform | I1: Link | J1: Status | K1: Confidence | L1: Attempts | M1: Last Revised | N1: Next Revision | O1: Due? | P1: Notes
A2: 1 | B2: 1. Foundations - Core | C2: 01. Basics & Recursion | D2: Recursion warm-up | E2: Print 1 to N using Recursion | F2: Easy | G2: Core | H2: GeeksforGeeks | I2: https://www.geeksforgeeks.org/problems/print-1-to-n-without-using-loops3621/1 | J2: Not Started | N2: =IF($M2="","",$M2+IF($K2="",Dashboard!$M$9,INDEX(Dashboard!$M$5:$M$9,$K2))) | O2: =IF(OR($J2="Attempted",$J2="Revisit"),"DUE",IF($N2="","",IF($N2<=TODAY(),"DUE","")))
A3: 2 | B3: 1. Foundations - Core | C3: 01. Basics & Recursion | D3: Recursion warm-up | E3: Sum of First N Natural Numbers | F3: Easy | G3: Core | H3: GeeksforGeeks | I3: https://www.geeksforgeeks.org/problems/reverse-coding2452/1 | J3: Not Started | N3: =IF($M3="","",$M3+IF($K3="",Dashboard!$M$9,INDEX(Dashboard!$M$5:$M$9,$K3))) | O3: =IF(OR($J3="Attempted",$J3="Revisit"),"DUE",IF($N3="","",IF($N3<=TODAY(),"DUE","")))
A4: 3 | B4: 1. Foundations - Core | C4: 01. Basics & Recursion | D4: Recursion warm-up | E4: Factorial of a Number | F4: Easy | G4: Core | H4: GeeksforGeeks | I4: https://www.geeksforgeeks.org/problems/factorial5739/1 | J4: Not Started | N4: =IF($M4="","",$M4+IF($K4="",Dashboard!$M$9,INDEX(Dashboard!$M$5:$M$9,$K4))) | O4: =IF(OR($J4="Attempted",$J4="Revisit"),"DUE",IF($N4="","",IF($N4<=TODAY(),"DUE","")))
A5: 4 | B5: 1. Foundations - Core | C5: 01. Basics & Recursion | D5: Recursion warm-up | E5: Sum of Digits | F5: Easy | G5: Core | H5: GeeksforGeeks | I5: https://www.geeksforgeeks.org/problems/sum-of-digits1742/1 | J5: Not Started | N5: =IF($M5="","",$M5+IF($K5="",Dashboard!$M$9,INDEX(Dashboard!$M$5:$M$9,$K5))) | O5: =IF(OR($J5="Attempted",$J5="Revisit"),"DUE",IF($N5="","",IF($N5<=TODAY(),"DUE","")))
A6: 5 | B6: 1. Foundations - Core | C6: 01. Basics & Recursion | D6: Recursion warm-up | E6: Reverse an Array using Recursion | F6: Easy | G6: Core | H6: GeeksforGeeks | I6: https://www.geeksforgeeks.org/problems/reverse-an-array/1 | J6: Not Started | N6: =IF($M6="","",$M6+IF($K6="",Dashboard!$M$9,INDEX(Dashboard!$M$5:$M$9,$K6))) | O6: =IF(OR($J6="Attempted",$J6="Revisit"),"DUE",IF($N6="","",IF($N6<=TODAY(),"DUE","")))
A7: 6 | B7: 1. Foundations - Core | C7: 01. Basics & Recursion | D7: Recursion warm-up | E7: Palindrome String (recursive) | F7: Easy | G7: Core | H7: GeeksforGeeks | I7: https://www.geeksforgeeks.org/problems/palindrome-string0817/1 | J7: Not Started | N7: =IF($M7="","",$M7+IF($K7="",Dashboard!$M$9,INDEX(Dashboard!$M$5:$M$9,$K7))) | O7: =IF(OR($J7="Attempted",$J7="Revisit"),"DUE",IF($N7="","",IF($N7<=TODAY(),"DUE","")))
A8: 7 | B8: 1. Foundations - Core | C8: 01. Basics & Recursion | D8: Recursion warm-up | E8: Check if an Array is Sorted | F8: Easy | G8: Core | H8: GeeksforGeeks | I8: https://www.geeksforgeeks.org/problems/check-if-an-array-is-sorted0701/1 | J8: Not Started | N8: =IF($M8="","",$M8+IF($K8="",Dashboard!$M$9,INDEX(Dashboard!$M$5:$M$9,$K8))) | O8: =IF(OR($J8="Attempted",$J8="Revisit"),"DUE",IF($N8="","",IF($N8<=TODAY(),"DUE","")))
A9: 8 | B9: 1. Foundations - Core | C9: 01. Basics & Recursion | D9: Recursion warm-up | E9: Remove All Occurrences of a Character | F9: Easy | G9: Core | H9: GeeksforGeeks | I9: https://www.geeksforgeeks.org/problems/remove-all-occurrences-of-a-character-in-a-string/1 | J9: Not Started | N9: =IF($M9="","",$M9+IF($K9="",Dashboard!$M$9,INDEX(Dashboard!$M$5:$M$9,$K9))) | O9: =IF(OR($J9="Attempted",$J9="Revisit"),"DUE",IF($N9="","",IF($N9<=TODAY(),"DUE","")))
A10: 9 | B10: 1. Foundations - Core | C10: 01. Basics & Recursion | D10: Recursion warm-up | E10: Fibonacci Number | F10: Easy | G10: Core | H10: LeetCode | I10: https://leetcode.com/problems/fibonacci-number/ | J10: Not Started | N10: =IF($M10="","",$M10+IF($K10="",Dashboard!$M$9,INDEX(Dashboard!$M$5:$M$9,$K10))) | O10: =IF(OR($J10="Attempted",$J10="Revisit"),"DUE",IF($N10="","",IF($N10<=TODAY(),"DUE","")))
A11: 10 | B11: 1. Foundations - Core | C11: 01. Basics & Recursion | D11: Recursion warm-up | E11: Pow(x, n) | F11: Medium | G11: Core | H11: LeetCode | I11: https://leetcode.com/problems/powx-n/ | J11: Not Started | N11: =IF($M11="","",$M11+IF($K11="",Dashboard!$M$9,INDEX(Dashboard!$M$5:$M$9,$K11))) | O11: =IF(OR($J11="Attempted",$J11="Revisit"),"DUE",IF($N11="","",IF($N11<=TODAY(),"DUE","")))
A12: 11 | B12: 1. Foundations - Core | C12: 01. Basics & Recursion | D12: Divide & Conquer | E12: Merge Sort | F12: Medium | G12: Core | H12: GeeksforGeeks | I12: https://www.geeksforgeeks.org/problems/merge-sort/1 | J12: Not Started | N12: =IF($M12="","",$M12+IF($K12="",Dashboard!$M$9,INDEX(Dashboard!$M$5:$M$9,$K12))) | O12: =IF(OR($J12="Attempted",$J12="Revisit"),"DUE",IF($N12="","",IF($N12<=TODAY(),"DUE","")))
A13: 12 | B13: 1. Foundations - Core | C13: 01. Basics & Recursion | D13: Divide & Conquer | E13: Quick Sort | F13: Medium | G13: Core | H13: GeeksforGeeks | I13: https://www.geeksforgeeks.org/problems/quick-sort/1 | J13: Not Started | N13: =IF($M13="","",$M13+IF($K13="",Dashboard!$M$9,INDEX(Dashboard!$M$5:$M$9,$K13))) | O13: =IF(OR($J13="Attempted",$J13="Revisit"),"DUE",IF($N13="","",IF($N13<=TODAY(),"DUE","")))
... A18: 17 | B18: 1. Foundations - Core | C18: 02. Arrays & Two Pointers | D18: Basics | E18: Third Maximum Number | F18: Easy | G18: Core | H18: LeetCode | I18: https://leetcode.com/problems/third-maximum-number/ | J18: Not Started | N18: =IF($M18="","",$M18+IF($K18="",Dashboard!$M$9,INDEX(Dashboard!$M$5:$M$9,$K18))) | O18: =IF(OR($J18="Attempted",$J18="Revisit"),"DUE",IF($N18="","",IF($N18<=TODAY(),"DUE","")))
A19: 18 | B19: 1. Foundations - Core | C19: 02. Arrays & Two Pointers | D19: Two pointers | E19: Remove Duplicates from Sorted Array | F19: Easy | G19: Core | H19: LeetCode | I19: https://leetcode.com/problems/remove-duplicates-from-sorted-array/ | J19: Not Started | N19: =IF($M19="","",$M19+IF($K19="",Dashboard!$M$9,INDEX(Dashboard!$M$5:$M$9,$K19))) | O19: =IF(OR($J19="Attempted",$J19="Revisit"),"DUE",IF($N19="","",IF($N19<=TODAY(),"DUE",""))) | P19: v3 addition
A20: 19 | B20: 1. Foundations - Core | C20: 02. Arrays & Two Pointers | D20: Two pointers | E20: Move Zeroes | F20: Easy | G20: Core | H20: LeetCode | I20: https://leetcode.com/problems/move-zeroes/ | J20: Not Started | N20: =IF($M20="","",$M20+IF($K20="",Dashboard!$M$9,INDEX(Dashboard!$M$5:$M$9,$K20))) | O20: =IF(OR($J20="Attempted",$J20="Revisit"),"DUE",IF($N20="","",IF($N20<=TODAY(),"DUE",""))) | P20: v3 addition
A21: 20 | B21: 1. Foundations - Core | C21: 02. Arrays & Two Pointers | D21: Two pointers | E21: Sort Array By Parity | F21: Easy | G21: Core | H21: LeetCode | I21: https://leetcode.com/problems/sort-array-by-parity/ | J21: Not Started | N21: =IF($M21="","",$M21+IF($K21="",Dashboard!$M$9,INDEX(Dashboard!$M$5:$M$9,$K21))) | O21: =IF(OR($J21="Attempted",$J21="Revisit"),"DUE",IF($N21="","",IF($N21<=TODAY(),"DUE",""))) | P21: v3 addition
A22: 21 | B22: 1. Foundations - Core | C22: 02. Arrays & Two Pointers | D22: Two pointers | E22: Two Sum II - Input Array Is Sorted | F22: Medium | G22: Core | H22: LeetCode | I22: https://leetcode.com/problems/two-sum-ii-input-array-is-sorted/ | J22: Not Started | N22: =IF($M22="","",$M22+IF($K22="",Dashboard!$M$9,INDEX(Dashboard!$M$5:$M$9,$K22))) | O22: =IF(OR($J22="Attempted",$J22="Revisit"),"DUE",IF($N22="","",IF($N22<=TODAY(),"DUE","")))
A23: 22 | B23: 1. Foundations - Core | C23: 02. Arrays & Two Pointers | D23: Dutch National Flag | E23: Segregate 0s and 1s | F23: Easy | G23: Core | H23: GeeksforGeeks | I23: https://www.geeksforgeeks.org/problems/segregate-0s-and-1s5106/1 | J23: Not Started | N23: =IF($M23="","",$M23+IF($K23="",Dashboard!$M$9,INDEX(Dashboard!$M$5:$M$9,$K23))) | O23: =IF(OR($J23="Attempted",$J23="Revisit"),"DUE",IF($N23="","",IF($N23<=TODAY(),"DUE","")))
A24: 23 | B24: 1. Foundations - Core | C24: 02. Arrays & Two Pointers | D24: Dutch National Flag | E24: Sort Colors | F24: Medium | G24: Core | H24: LeetCode | I24: https://leetcode.com/problems/sort-colors/ | J24: Not Started | N24: =IF($M24="","",$M24+IF($K24="",Dashboard!$M$9,INDEX(Dashboard!$M$5:$M$9,$K24))) | O24: =IF(OR($J24="Attempted",$J24="Revisit"),"DUE",IF($N24="","",IF($N24<=TODAY(),"DUE","")))
A25: 24 | B25: 1. Foundations - Core | C25: 02. Arrays & Two Pointers | D25: Frequency scan | E25: Element Appearing More Than 25% In Sorted Array | F25: Easy | G25: Core | H25: LeetCode | I25: https://leetcode.com/problems/element-appearing-more-than-25-in-sorted-array/ | J25: Not Started | N25: =IF($M25="","",$M25+IF($K25="",Dashboard!$M$9,INDEX(Dashboard!$M$5:$M$9,$K25))) | O25: =IF(OR($J25="Attempted",$J25="Revisit"),"DUE",IF($N25="","",IF($N25<=TODAY(),"DUE",""))) | P25: v3 addition
A26: 25 | B26: 1. Foundations - Core | C26: 02. Arrays & Two Pointers | D26: Frequency scan | E26: Most Frequent Even Element | F26: Easy | G26: Core | H26: LeetCode | I26: https://leetcode.com/problems/most-frequent-even-element/ | J26: Not Started | N26: =IF($M26="","",$M26+IF($K26="",Dashboard!$M$9,INDEX(Dashboard!$M$5:$M$9,$K26))) | O26: =IF(OR($J26="Attempted",$J26="Revisit"),"DUE",IF($N26="","",IF($N26<=TODAY(),"DUE","")))
A27: 26 | B27: 1. Foundations - Core | C27: 02. Arrays & Two Pointers | D27: Voting / counting | E27: Majority Element | F27: Easy | G27: Core | H27: LeetCode | I27: https://leetcode.com/problems/majority-element/ | J27: Not Started | N27: =IF($M27="","",$M27+IF($K27="",Dashboard!$M$9,INDEX(Dashboard!$M$5:$M$9,$K27))) | O27: =IF(OR($J27="Attempted",$J27="Revisit"),"DUE",IF($N27="","",IF($N27<=TODAY(),"DUE",""))) | P27: v3 addition
A28: 27 | B28: 1. Foundations - Core | C28: 02. Arrays & Two Pointers | D28: Voting / counting | E28: Majority Element II | F28: Medium | G28: Core | H28: LeetCode | I28: https://leetcode.com/problems/majority-element-ii/ | J28: Not Started | N28: =IF($M28="","",$M28+IF($K28="",Dashboard!$M$9,INDEX(Dashboard!$M$5:$M$9,$K28))) | O28: =IF(OR($J28="Attempted",$J28="Revisit"),"DUE",IF($N28="","",IF($N28<=TODAY(),"DUE",""))) | P28: v3 addition
A29: 28 | B29: 1. Foundations - Core | C29: 02. Arrays & Two Pointers | D29: Rearrangement | E29: Rotate Array | F29: Medium | G29: Core | H29: LeetCode | I29: https://leetcode.com/problems/rotate-array/ | J29: Not Started | N29: =IF($M29="","",$M29+IF($K29="",Dashboard!$M$9,INDEX(Dashboard!$M$5:$M$9,$K29))) | O29: =IF(OR($J29="Attempted",$J29="Revisit"),"DUE",IF($N29="","",IF($N29<=TODAY(),"DUE",""))) | P29: v3 addition
A30: 29 | B30: 1. Foundations - Core | C30: 02. Arrays & Two Pointers | D30: Rearrangement | E30: Next Permutation | F30: Medium | G30: Core | H30: LeetCode | I30: https://leetcode.com/problems/next-permutation/ | J30: Not Started | N30: =IF($M30="","",$M30+IF($K30="",Dashboard!$M$9,INDEX(Dashboard!$M$5:$M$9,$K30))) | O30: =IF(OR($J30="Attempted",$J30="Revisit"),"DUE",IF($N30="","",IF($N30<=TODAY(),"DUE","")))
A31: 30 | B31: 1. Foundations - Core | C31: 02. Arrays & Two Pointers | D31: K-Sum | E31: Number of Arithmetic Triplets | F31: Easy | G31: Core | H31: LeetCode | I31: https://leetcode.com/problems/number-of-arithmetic-triplets/ | J31: Not Started | N31: =IF($M31="","",$M31+IF($K31="",Dashboard!$M$9,INDEX(Dashboard!$M$5:$M$9,$K31))) | O31: =IF(OR($J31="Attempted",$J31="Revisit"),"DUE",IF($N31="","",IF($N31<=TODAY(),"DUE","")))
A32: 31 | B32: 1. Foundations - Core | C32: 02. Arrays & Two Pointers | D32: K-Sum | E32: 3Sum | F32: Medium | G32: Core | H32: LeetCode | I32: https://leetcode.com/problems/3sum/ | J32: Not Started | N32: =IF($M32="","",$M32+IF($K32="",Dashboard!$M$9,INDEX(Dashboard!$M$5:$M$9,$K32))) | O32: =IF(OR($J32="Attempted",$J32="Revisit"),"DUE",IF($N32="","",IF($N32<=TODAY(),"DUE","")))
A33: 32 | B33: 1. Foundations - Core | C33: 02. Arrays & Two Pointers | D33: K-Sum | E33: 3Sum Closest | F33: Medium | G33: Core | H33: LeetCode | I33: https://leetcode.com/problems/3sum-closest/ | J33: Not Started | N33: =IF($M33="","",$M33+IF($K33="",Dashboard!$M$9,INDEX(Dashboard!$M$5:$M$9,$K33))) | O33: =IF(OR($J33="Attempted",$J33="Revisit"),"DUE",IF($N33="","",IF($N33<=TODAY(),"DUE",""))) | P33: v3 addition
A34: 33 | B34: 1. Foundations - Core | C34: 03. Sorting & Cyclic Sort | D34: Custom comparator | E34: Relative Sort Array | F34: Easy | G34: Core | H34: LeetCode | I34: https://leetcode.com/problems/relative-sort-array/ | J34: Not Started | N34: =IF($M34="","",$M34+IF($K34="",Dashboard!$M$9,INDEX(Dashboard!$M$5:$M$9,$K34))) | O34: =IF(OR($J34="Attempted",$J34="Revisit"),"DUE",IF($N34="","",IF($N34<=TODAY(),"DUE","")))
A35: 34 | B35: 1. Foundations - Core | C35: 03. Sorting & Cyclic Sort | D35: Custom comparator | E35: Rank Transform of an Array | F35: Easy | G35: Core | H35: LeetCode | I35: https://leetcode.com/problems/rank-transform-of-an-array/ | J35: Not Started | N35: =IF($M35="","",$M35+IF($K35="",Dashboard!$M$9,INDEX(Dashboard!$M$5:$M$9,$K35))) | O35: =IF(OR($J35="Attempted",$J35="Revisit"),"DUE",IF($N35="","",IF($N35<=TODAY(),"DUE","")))
A36: 35 | B36: 1. Foundations - Core | C36: 03. Sorting & Cyclic Sort | D36: Custom comparator | E36: Largest Number | F36: Medium | G36: Core | H36: LeetCode | I36: https://leetcode.com/problems/largest-number/ | J36: Not Started | N36: =IF($M36="","",$M36+IF($K36="",Dashboard!$M$9,INDEX(Dashboard!$M$5:$M$9,$K36))) | O36: =IF(OR($J36="Attempted",$J36="Revisit"),"DUE",IF($N36="","",IF($N36<=TODAY(),"DUE","")))
A37: 36 | B37: 1. Foundations - Core | C37: 03. Sorting & Cyclic Sort | D37: Counting sort | E37: Sort an Array by Increasing Frequency | F37: Easy | G37: Core | H37: LeetCode | I37: https://leetcode.com/problems/sort-array-by-increasing-frequency/ | J37: Not Started | N37: =IF($M37="","",$M37+IF($K37="",Dashboard!$M$9,INDEX(Dashboard!$M$5:$M$9,$K37))) | O37: =IF(OR($J37="Attempted",$J37="Revisit"),"DUE",IF($N37="","",IF($N37<=TODAY(),"DUE","")))
A38: 37 | B38: 1. Foundations - Core | C38: 03. Sorting & Cyclic Sort | D38: Counting sort | E38: Height Checker | F38: Easy | G38: Core | H38: LeetCode | I38: https://leetcode.com/problems/height-checker/ | J38: Not Started | N38: =IF($M38="","",$M38+IF($K38="",Dashboard!$M$9,INDEX(Dashboard!$M$5:$M$9,$K38))) | O38: =IF(OR($J38="Attempted",$J38="Revisit"),"DUE",IF($N38="","",IF($N38<=TODAY(),"DUE",""))) | P38: v3 addition
A39: 38 | B39: 1. Foundations - Core | C39: 03. Sorting & Cyclic Sort | D39: Counting sort | E39: Sort Even and Odd Indices Independently | F39: Easy | G39: Core | H39: LeetCode | I39: https://leetcode.com/problems/sort-even-and-odd-indices-independently/ | J39: Not Started | N39: =IF($M39="","",$M39+IF($K39="",Dashboard!$M$9,INDEX(Dashboard!$M$5:$M$9,$K39))) | O39: =IF(OR($J39="Attempted",$J39="Revisit"),"DUE",IF($N39="","",IF($N39<=TODAY(),"DUE","")))
A40: 39 | B40: 1. Foundations - Core | C40: 03. Sorting & Cyclic Sort | D40: Counting sort | E40: Maximum Number of Balls in a Box | F40: Easy | G40: Core | H40: LeetCode | I40: https://leetcode.com/problems/maximum-number-of-balls-in-a-box/ | J40: Not Started | N40: =IF($M40="","",$M40+IF($K40="",Dashboard!$M$9,INDEX(Dashboard!$M$5:$M$9,$K40))) | O40: =IF(OR($J40="Attempted",$J40="Revisit"),"DUE",IF($N40="","",IF($N40<=TODAY(),"DUE","")))
A41: 40 | B41: 1. Foundations - Core | C41: 03. Sorting & Cyclic Sort | D41: Cyclic sort | E41: Missing Number | F41: Easy | G41: Core | H41: LeetCode | I41: https://leetcode.com/problems/missing-number/ | J41: Not Started | N41: =IF($M41="","",$M41+IF($K41="",Dashboard!$M$9,INDEX(Dashboard!$M$5:$M$9,$K41))) | O41: =IF(OR($J41="Attempted",$J41="Revisit"),"DUE",IF($N41="","",IF($N41<=TODAY(),"DUE","")))
A42: 41 | B42: 1. Foundations - Core | C42: 03. Sorting & Cyclic Sort | D42: Cyclic sort | E42: Find All Numbers Disappeared in an Array | F42: Easy | G42: Core | H42: LeetCode | I42: https://leetcode.com/problems/find-all-numbers-disappeared-in-an-array/ | J42: Not Started | N42: =IF($M42="","",$M42+IF($K42="",Dashboard!$M$9,INDEX(Dashboard!$M$5:$M$9,$K42))) | O42: =IF(OR($J42="Attempted",$J42="Revisit"),"DUE",IF($N42="","",IF($N42<=TODAY(),"DUE","")))
A43: 42 | B43: 1. Foundations - Core | C43: 03. Sorting & Cyclic Sort | D43: Sorting application | E43: Largest Perimeter Triangle | F43: Easy | G43: Core | H43: LeetCode | I43: https://leetcode.com/problems/largest-perimeter-triangle/ | J43: Not Started | N43: =IF($M43="","",$M43+IF($K43="",Dashboard!$M$9,INDEX(Dashboard!$M$5:$M$9,$K43))) | O43: =IF(OR($J43="Attempted",$J43="Revisit"),"DUE",IF($N43="","",IF($N43<=TODAY(),"DUE","")))
A44: 43 | B44: 1. Foundations - Core | C44: 03. Sorting & Cyclic Sort | D44: Sorting application | E44: Minimum Absolute Difference | F44: Easy | G44: Core | H44: LeetCode | I44: https://leetcode.com/problems/minimum-absolute-difference/ | J44: Not Started | N44: =IF($M44="","",$M44+IF($K44="",Dashboard!$M$9,INDEX(Dashboard!$M$5:$M$9,$K44))) | O44: =IF(OR($J44="Attempted",$J44="Revisit"),"DUE",IF($N44="","",IF($N44<=TODAY(),"DUE","")))
...

Sheet Dashboard
B2: Progress Dashboard
B3: Every number here is calculated from the Master tab. Do not type into this sheet except the yellow config cells. | L3: CONFIG - revision gap (days)
L4: Confidence | M4: Days
B5: CORE TRACK (the one that matters) | C5: =COUNTIFS(Master!$G$2:$G$918,"Core",Master!$J$2:$J$918,"Solved")+COUNTIFS(Master!$G$2:$G$918,"Core",Master!$J$2:$J$918,"Mastered") | D5: =COUNTIF(Master!$G$2:$G$918,"Core") | E5: =IFERROR($C5/$D5,0) | L5: 1 | M5: 2
B6: All 922 questions | C6: =COUNTIF(Master!$J$2:$J$918,"Solved")+COUNTIF(Master!$J$2:$J$918,"Mastered") | D6: =COUNTA(Master!$A$2:$A$918) | E6: =IFERROR($C6/$D6,0) | L6: 2 | M6: 4
B7: Due for revision today | C7: =COUNTIF(Master!$O$2:$O$918,"DUE") | L7: 3 | M7: 7
L8: 4 | M8: 21
B9: Topic | C9: Total | D9: Core | E9: Done | F9: Core done | G9: Attempted | H9: Avg conf | I9: % Core done | L9: 5 | M9: 45
B10: 01. Basics & Recursion | C10: =COUNTIF(Master!$C$2:$C$918,$B10) | D10: =COUNTIFS(Master!$C$2:$C$918,$B10,Master!$G$2:$G$918,"Core") | E10: =COUNTIFS(Master!$C$2:$C$918,$B10,Master!$J$2:$J$918,"Solved")+COUNTIFS(Master!$C$2:$C$918,$B10,Master!$J$2:$J$918,"Mastered") | F10: =COUNTIFS(Master!$C$2:$C$918,$B10,Master!$G$2:$G$918,"Core",Master!$J$2:$J$918,"Solved")+COUNTIFS(Master!$C$2:$C$918,$B10,Master!$G$2:$G$918,"Core",Master!$J$2:$J$918,"Mastered") | G10: =COUNTIFS(Master!$C$2:$C$918,$B10,Master!$J$2:$J$918,"Attempted")+COUNTIFS(Master!$C$2:$C$918,$B10,Master!$J$2:$J$918,"Revisit") | H10: =IFERROR(AVERAGEIFS(Master!$K$2:$K$918,Master!$C$2:$C$918,$B10),"") | I10: =IFERROR($F10/$C10,0) | L10: Editable. Master!N uses these to set Next Revision.
B11: 02. Arrays & Two Pointers | C11: =COUNTIF(Master!$C$2:$C$918,$B11) | D11: =COUNTIFS(Master!$C$2:$C$918,$B11,Master!$G$2:$G$918,"Core") | E11: =COUNTIFS(Master!$C$2:$C$918,$B11,Master!$J$2:$J$918,"Solved")+COUNTIFS(Master!$C$2:$C$918,$B11,Master!$J$2:$J$918,"Mastered") | F11: =COUNTIFS(Master!$C$2:$C$918,$B11,Master!$G$2:$G$918,"Core",Master!$J$2:$J$918,"Solved")+COUNTIFS(Master!$C$2:$C$918,$B11,Master!$G$2:$G$918,"Core",Master!$J$2:$J$918,"Mastered") | G11: =COUNTIFS(Master!$C$2:$C$918,$B11,Master!$J$2:$J$918,"Attempted")+COUNTIFS(Master!$C$2:$C$918,$B11,Master!$J$2:$J$918,"Revisit") | H11: =IFERROR(AVERAGEIFS(Master!$K$2:$K$918,Master!$C$2:$C$918,$B11),"") | I11: =IFERROR($F11/$C11,0)
B12: 03. Sliding Window | C12: =COUNTIF(Master!$C$2:$C$918,$B12) | D12: =COUNTIFS(Master!$C$2:$C$918,$B12,Master!$G$2:$G$918,"Core") | E12: =COUNTIFS(Master!$C$2:$C$918,$B12,Master!$J$2:$J$918,"Solved")+COUNTIFS(Master!$C$2:$C$918,$B12,Master!$J$2:$J$918,"Mastered") | F12: =COUNTIFS(Master!$C$2:$C$918,$B12,Master!$G$2:$G$918,"Core",Master!$J$2:$J$918,"Solved")+COUNTIFS(Master!$C$2:$C$918,$B12,Master!$G$2:$G$918,"Core",Master!$J$2:$J$918,"Mastered") | G12: =COUNTIFS(Master!$C$2:$C$918,$B12,Master!$J$2:$J$918,"Attempted")+COUNTIFS(Master!$C$2:$C$918,$B12,Master!$J$2:$J$918,"Revisit") | H12: =IFERROR(AVERAGEIFS(Master!$K$2:$K$918,Master!$C$2:$C$918,$B12),"") | I12: =IFERROR($F12/$C12,0)
B13: 04. Prefix Sum & Kadane | C13: =COUNTIF(Master!$C$2:$C$918,$B13) | D13: =COUNTIFS(Master!$C$2:$C$918,$B13,Master!$G$2:$G$918,"Core") | E13: =COUNTIFS(Master!$C$2:$C$918,$B13,Master!$J$2:$J$918,"Solved")+COUNTIFS(Master!$C$2:$C$918,$B13,Master!$J$2:$J$918,"Mastered") | F13: =COUNTIFS(Master!$C$2:$C$918,$B13,Master!$G$2:$G$918,"Core",Master!$J$2:$J$918,"Solved")+COUNTIFS(Master!$C$2:$C$918,$B13,Master!$G$2:$G$918,"Core",Master!$J$2:$J$918,"Mastered") | G13: =COUNTIFS(Master!$C$2:$C$918,$B13,Master!$J$2:$J$918,"Attempted")+COUNTIFS(Master!$C$2:$C$918,$B13,Master!$J$2:$J$918,"Revisit") | H13: =IFERROR(AVERAGEIFS(Master!$K$2:$K$918,Master!$C$2:$C$918,$B13),"") | I13: =IFERROR($F13/$C13,0)
B14: 05. Sorting & Cyclic Sort | C14: =COUNTIF(Master!$C$2:$C$918,$B14) | D14: =COUNTIFS(Master!$C$2:$C$918,$B14,Master!$G$2:$G$918,"Core") | E14: =COUNTIFS(Master!$C$2:$C$918,$B14,Master!$J$2:$J$918,"Solved")+COUNTIFS(Master!$C$2:$C$918,$B14,Master!$J$2:$J$918,"Mastered") | F14: =COUNTIFS(Master!$C$2:$C$918,$B14,Master!$G$2:$G$918,"Core",Master!$J$2:$J$918,"Solved")+COUNTIFS(Master!$C$2:$C$918,$B14,Master!$G$2:$G$918,"Core",Master!$J$2:$J$918,"Mastered") | G14: =COUNTIFS(Master!$C$2:$C$918,$B14,Master!$J$2:$J$918,"Attempted")+COUNTIFS(Master!$C$2:$C$918,$B14,Master!$J$2:$J$918,"Revisit") | H14: =IFERROR(AVERAGEIFS(Master!$K$2:$K$918,Master!$C$2:$C$918,$B14),"") | I14: =IFERROR($F14/$C14,0)
B15: 06. Binary Search | C15: =COUNTIF(Master!$C$2:$C$918,$B15) | D15: =COUNTIFS(Master!$C$2:$C$918,$B15,Master!$G$2:$G$918,"Core") | E15: =COUNTIFS(Master!$C$2:$C$918,$B15,Master!$J$2:$J$918,"Solved")+COUNTIFS(Master!$C$2:$C$918,$B15,Master!$J$2:$J$918,"Mastered") | F15: =COUNTIFS(Master!$C$2:$C$918,$B15,Master!$G$2:$G$918,"Core",Master!$J$2:$J$918,"Solved")+COUNTIFS(Master!$C$2:$C$918,$B15,Master!$G$2:$G$918,"Core",Master!$J$2:$J$918,"Mastered") | G15: =COUNTIFS(Master!$C$2:$C$918,$B15,Master!$J$2:$J$918,"Attempted")+COUNTIFS(Master!$C$2:$C$918,$B15,Master!$J$2:$J$918,"Revisit") | H15: =IFERROR(AVERAGEIFS(Master!$K$2:$K$918,Master!$C$2:$C$918,$B15),"") | I15: =IFERROR($F15/$C15,0)
B16: 07. Strings | C16: =COUNTIF(Master!$C$2:$C$918,$B16) | D16: =COUNTIFS(Master!$C$2:$C$918,$B16,Master!$G$2:$G$918,"Core") | E16: =COUNTIFS(Master!$C$2:$C$918,$B16,Master!$J$2:$J$918,"Solved")+COUNTIFS(Master!$C$2:$C$918,$B16,Master!$J$2:$J$918,"Mastered") | F16: =COUNTIFS(Master!$C$2:$C$918,$B16,Master!$G$2:$G$918,"Core",Master!$J$2:$J$918,"Solved")+COUNTIFS(Master!$C$2:$C$918,$B16,Master!$G$2:$G$918,"Core",Master!$J$2:$J$918,"Mastered") | G16: =COUNTIFS(Master!$C$2:$C$918,$B16,Master!$J$2:$J$918,"Attempted")+COUNTIFS(Master!$C$2:$C$918,$B16,Master!$J$2:$J$918,"Revisit") | H16: =IFERROR(AVERAGEIFS(Master!$K$2:$K$918,Master!$C$2:$C$918,$B16),"") | I16: =IFERROR($F16/$C16,0)
B17: 08. Hashing | C17: =COUNTIF(Master!$C$2:$C$918,$B17) | D17: =COUNTIFS(Master!$C$2:$C$918,$B17,Master!$G$2:$G$918,"Core") | E17: =COUNTIFS(Master!$C$2:$C$918,$B17,Master!$J$2:$J$918,"Solved")+COUNTIFS(Master!$C$2:$C$918,$B17,Master!$J$2:$J$918,"Mastered") | F17: =COUNTIFS(Master!$C$2:$C$918,$B17,Master!$G$2:$G$918,"Core",Master!$J$2:$J$918,"Solved")+COUNTIFS(Master!$C$2:$C$918,$B17,Master!$G$2:$G$918,"Core",Master!$J$2:$J$918,"Mastered") | G17: =COUNTIFS(Master!$C$2:$C$918,$B17,Master!$J$2:$J$918,"Attempted")+COUNTIFS(Master!$C$2:$C$918,$B17,Master!$J$2:$J$918,"Revisit") | H17: =IFERROR(AVERAGEIFS(Master!$K$2:$K$918,Master!$C$2:$C$918,$B17),"") | I17: =IFERROR($F17/$C17,0)
B18: 09. Matrix / 2D | C18: =COUNTIF(Master!$C$2:$C$918,$B18) | D18: =COUNTIFS(Master!$C$2:$C$918,$B18,Master!$G$2:$G$918,"Core") | E18: =COUNTIFS(Master!$C$2:$C$918,$B18,Master!$J$2:$J$918,"Solved")+COUNTIFS(Master!$C$2:$C$918,$B18,Master!$J$2:$J$918,"Mastered") | F18: =COUNTIFS(Master!$C$2:$C$918,$B18,Master!$G$2:$G$918,"Core",Master!$J$2:$J$918,"Solved")+COUNTIFS(Master!$C$2:$C$918,$B18,Master!$G$2:$G$918,"Core",Master!$J$2:$J$918,"Mastered") | G18: =COUNTIFS(Master!$C$2:$C$918,$B18,Master!$J$2:$J$918,"Attempted")+COUNTIFS(Master!$C$2:$C$918,$B18,Master!$J$2:$J$918,"Revisit") | H18: =IFERROR(AVERAGEIFS(Master!$K$2:$K$918,Master!$C$2:$C$918,$B18),"") | I18: =IFERROR($F18/$C18,0)
B19: 10. Linked List | C19: =COUNTIF(Master!$C$2:$C$918,$B19) | D19: =COUNTIFS(Master!$C$2:$C$918,$B19,Master!$G$2:$G$918,"Core") | E19: =COUNTIFS(Master!$C$2:$C$918,$B19,Master!$J$2:$J$918,"Solved")+COUNTIFS(Master!$C$2:$C$918,$B19,Master!$J$2:$J$918,"Mastered") | F19: =COUNTIFS(Master!$C$2:$C$918,$B19,Master!$G$2:$G$918,"Core",Master!$J$2:$J$918,"Solved")+COUNTIFS(Master!$C$2:$C$918,$B19,Master!$G$2:$G$918,"Core",Master!$J$2:$J$918,"Mastered") | G19: =COUNTIFS(Master!$C$2:$C$918,$B19,Master!$J$2:$J$918,"Attempted")+COUNTIFS(Master!$C$2:$C$918,$B19,Master!$J$2:$J$918,"Revisit") | H19: =IFERROR(AVERAGEIFS(Master!$K$2:$K$918,Master!$C$2:$C$918,$B19),"") | I19: =IFERROR($F19/$C19,0)
B20: 11. Stack & Queue | C20: =COUNTIF(Master!$C$2:$C$918,$B20) | D20: =COUNTIFS(Master!$C$2:$C$918,$B20,Master!$G$2:$G$918,"Core") | E20: =COUNTIFS(Master!$C$2:$C$918,$B20,Master!$J$2:$J$918,"Solved")+COUNTIFS(Master!$C$2:$C$918,$B20,Master!$J$2:$J$918,"Mastered") | F20: =COUNTIFS(Master!$C$2:$C$918,$B20,Master!$G$2:$G$918,"Core",Master!$J$2:$J$918,"Solved")+COUNTIFS(Master!$C$2:$C$918,$B20,Master!$G$2:$G$918,"Core",Master!$J$2:$J$918,"Mastered") | G20: =COUNTIFS(Master!$C$2:$C$918,$B20,Master!$J$2:$J$918,"Attempted")+COUNTIFS(Master!$C$2:$C$918,$B20,Master!$J$2:$J$918,"Revisit") | H20: =IFERROR(AVERAGEIFS(Master!$K$2:$K$918,Master!$C$2:$C$918,$B20),"") | I20: =IFERROR($F20/$C20,0)
B21: 12. Heap & Priority Queue | C21: =COUNTIF(Master!$C$2:$C$918,$B21) | D21: =COUNTIFS(Master!$C$2:$C$918,$B21,Master!$G$2:$G$918,"Core") | E21: =COUNTIFS(Master!$C$2:$C$918,$B21,Master!$J$2:$J$918,"Solved")+COUNTIFS(Master!$C$2:$C$918,$B21,Master!$J$2:$J$918,"Mastered") | F21: =COUNTIFS(Master!$C$2:$C$918,$B21,Master!$G$2:$G$918,"Core",Master!$J$2:$J$918,"Solved")+COUNTIFS(Master!$C$2:$C$918,$B21,Master!$G$2:$G$918,"Core",Master!$J$2:$J$918,"Mastered") | G21: =COUNTIFS(Master!$C$2:$C$918,$B21,Master!$J$2:$J$918,"Attempted")+COUNTIFS(Master!$C$2:$C$918,$B21,Master!$J$2:$J$918,"Revisit") | H21: =IFERROR(AVERAGEIFS(Master!$K$2:$K$918,Master!$C$2:$C$918,$B21),"") | I21: =IFERROR($F21/$C21,0)
B22: 13. Greedy | C22: =COUNTIF(Master!$C$2:$C$918,$B22) | D22: =COUNTIFS(Master!$C$2:$C$918,$B22,Master!$G$2:$G$918,"Core") | E22: =COUNTIFS(Master!$C$2:$C$918,$B22,Master!$J$2:$J$918,"Solved")+COUNTIFS(Master!$C$2:$C$918,$B22,Master!$J$2:$J$918,"Mastered") | F22: =COUNTIFS(Master!$C$2:$C$918,$B22,Master!$G$2:$G$918,"Core",Master!$J$2:$J$918,"Solved")+COUNTIFS(Master!$C$2:$C$918,$B22,Master!$G$2:$G$918,"Core",Master!$J$2:$J$918,"Mastered") | G22: =COUNTIFS(Master!$C$2:$C$918,$B22,Master!$J$2:$J$918,"Attempted")+COUNTIFS(Master!$C$2:$C$918,$B22,Master!$J$2:$J$918,"Revisit") | H22: =IFERROR(AVERAGEIFS(Master!$K$2:$K$918,Master!$C$2:$C$918,$B22),"") | I22: =IFERROR($F22/$C22,0)
... B32: 23. Advanced DS | C32: =COUNTIF(Master!$C$2:$C$918,$B32) | D32: =COUNTIFS(Master!$C$2:$C$918,$B32,Master!$G$2:$G$918,"Core") | E32: =COUNTIFS(Master!$C$2:$C$918,$B32,Master!$J$2:$J$918,"Solved")+COUNTIFS(Master!$C$2:$C$918,$B32,Master!$J$2:$J$918,"Mastered") | F32: =COUNTIFS(Master!$C$2:$C$918,$B32,Master!$G$2:$G$918,"Core",Master!$J$2:$J$918,"Solved")+COUNTIFS(Master!$C$2:$C$918,$B32,Master!$G$2:$G$918,"Core",Master!$J$2:$J$918,"Mastered") | G32: =COUNTIFS(Master!$C$2:$C$918,$B32,Master!$J$2:$J$918,"Attempted")+COUNTIFS(Master!$C$2:$C$918,$B32,Master!$J$2:$J$918,"Revisit") | H32: =IFERROR(AVERAGEIFS(Master!$K$2:$K$918,Master!$C$2:$C$918,$B32),"") | I32: =IFERROR($F32/$C32,0)
B33: TOTAL | C33: =SUM(C10:C32) | D33: =SUM(D10:D32) | E33: =SUM(E10:E32) | F33: =SUM(F10:F32) | G33: =SUM(G10:G32) | H33: =IFERROR(AVERAGEIFS(Master!$K$2:$K$918,Master!$K$2:$K$918,">0"),"") | I33: =IFERROR($F33/$C33,0)
B35: By difficulty | G35: By status
C36: Total | D36: Done | E36: % | H36: Count
B37: Easy | C37: =COUNTIF(Master!$F$2:$F$918,$B37) | D37: =COUNTIFS(Master!$F$2:$F$918,$B37,Master!$J$2:$J$918,"Solved")+COUNTIFS(Master!$F$2:$F$918,$B37,Master!$J$2:$J$918,"Mastered") | E37: =IFERROR($D37/$C37,0) | G37: Not Started | H37: =COUNTIF(Master!$J$2:$J$918,$G37)
B38: Medium | C38: =COUNTIF(Master!$F$2:$F$918,$B38) | D38: =COUNTIFS(Master!$F$2:$F$918,$B38,Master!$J$2:$J$918,"Solved")+COUNTIFS(Master!$F$2:$F$918,$B38,Master!$J$2:$J$918,"Mastered") | E38: =IFERROR($D38/$C38,0) | G38: Attempted | H38: =COUNTIF(Master!$J$2:$J$918,$G38)
B39: Hard | C39: =COUNTIF(Master!$F$2:$F$918,$B39) | D39: =COUNTIFS(Master!$F$2:$F$918,$B39,Master!$J$2:$J$918,"Solved")+COUNTIFS(Master!$F$2:$F$918,$B39,Master!$J$2:$J$918,"Mastered") | E39: =IFERROR($D39/$C39,0) | G39: Solved | H39: =COUNTIF(Master!$J$2:$J$918,$G39)
G40: Mastered | H40: =COUNTIF(Master!$J$2:$J$918,$G40)
G41: Revisit | H41: =COUNTIF(Master!$J$2:$J$918,$G41)

Sheet Pattern Radar
B2: Pattern Radar
B3: Interviews test patterns, not problems. Sort by Verdict or Avg conf to find the exact hole. 'Weak' = average confidence 3 or below. 'Untouched' = nothing solved in this pattern yet.
B5: Topic | C5: Pattern | D5: Total | E5: Core | F5: Done | G5: Avg conf | H5: Verdict
B6: 01. Basics & Recursion | C6: Recursion warm-up | D6: =COUNTIFS(Master!$C$2:$C$918,$B6,Master!$D$2:$D$918,$C6) | E6: =COUNTIFS(Master!$C$2:$C$918,$B6,Master!$D$2:$D$918,$C6,Master!$G$2:$G$918,"Core") | F6: =COUNTIFS(Master!$C$2:$C$918,$B6,Master!$D$2:$D$918,$C6,Master!$J$2:$J$918,"Solved")+COUNTIFS(Master!$C$2:$C$918,$B6,Master!$D$2:$D$918,$C6,Master!$J$2:$J$918,"Mastered") | G6: =IFERROR(AVERAGEIFS(Master!$K$2:$K$918,Master!$C$2:$C$918,$B6,Master!$D$2:$D$918,$C6,Master!$K$2:$K$918,">0"),"") | H6: =IF($F6=0,"Untouched",IF($G6="","No rating",IF($G6<=3,"Weak","Solid")))
B7: 01. Basics & Recursion | C7: Divide & Conquer | D7: =COUNTIFS(Master!$C$2:$C$918,$B7,Master!$D$2:$D$918,$C7) | E7: =COUNTIFS(Master!$C$2:$C$918,$B7,Master!$D$2:$D$918,$C7,Master!$G$2:$G$918,"Core") | F7: =COUNTIFS(Master!$C$2:$C$918,$B7,Master!$D$2:$D$918,$C7,Master!$J$2:$J$918,"Solved")+COUNTIFS(Master!$C$2:$C$918,$B7,Master!$D$2:$D$918,$C7,Master!$J$2:$J$918,"Mastered") | G7: =IFERROR(AVERAGEIFS(Master!$K$2:$K$918,Master!$C$2:$C$918,$B7,Master!$D$2:$D$918,$C7,Master!$K$2:$K$918,">0"),"") | H7: =IF($F7=0,"Untouched",IF($G7="","No rating",IF($G7<=3,"Weak","Solid")))
B8: 02. Arrays & Two Pointers | C8: Basics | D8: =COUNTIFS(Master!$C$2:$C$918,$B8,Master!$D$2:$D$918,$C8) | E8: =COUNTIFS(Master!$C$2:$C$918,$B8,Master!$D$2:$D$918,$C8,Master!$G$2:$G$918,"Core") | F8: =COUNTIFS(Master!$C$2:$C$918,$B8,Master!$D$2:$D$918,$C8,Master!$J$2:$J$918,"Solved")+COUNTIFS(Master!$C$2:$C$918,$B8,Master!$D$2:$D$918,$C8,Master!$J$2:$J$918,"Mastered") | G8: =IFERROR(AVERAGEIFS(Master!$K$2:$K$918,Master!$C$2:$C$918,$B8,Master!$D$2:$D$918,$C8,Master!$K$2:$K$918,">0"),"") | H8: =IF($F8=0,"Untouched",IF($G8="","No rating",IF($G8<=3,"Weak","Solid")))
B9: 02. Arrays & Two Pointers | C9: Two pointers | D9: =COUNTIFS(Master!$C$2:$C$918,$B9,Master!$D$2:$D$918,$C9) | E9: =COUNTIFS(Master!$C$2:$C$918,$B9,Master!$D$2:$D$918,$C9,Master!$G$2:$G$918,"Core") | F9: =COUNTIFS(Master!$C$2:$C$918,$B9,Master!$D$2:$D$918,$C9,Master!$J$2:$J$918,"Solved")+COUNTIFS(Master!$C$2:$C$918,$B9,Master!$D$2:$D$918,$C9,Master!$J$2:$J$918,"Mastered") | G9: =IFERROR(AVERAGEIFS(Master!$K$2:$K$918,Master!$C$2:$C$918,$B9,Master!$D$2:$D$918,$C9,Master!$K$2:$K$918,">0"),"") | H9: =IF($F9=0,"Untouched",IF($G9="","No rating",IF($G9<=3,"Weak","Solid")))
B10: 02. Arrays & Two Pointers | C10: Dutch National Flag | D10: =COUNTIFS(Master!$C$2:$C$918,$B10,Master!$D$2:$D$918,$C10) | E10: =COUNTIFS(Master!$C$2:$C$918,$B10,Master!$D$2:$D$918,$C10,Master!$G$2:$G$918,"Core") | F10: =COUNTIFS(Master!$C$2:$C$918,$B10,Master!$D$2:$D$918,$C10,Master!$J$2:$J$918,"Solved")+COUNTIFS(Master!$C$2:$C$918,$B10,Master!$D$2:$D$918,$C10,Master!$J$2:$J$918,"Mastered") | G10: =IFERROR(AVERAGEIFS(Master!$K$2:$K$918,Master!$C$2:$C$918,$B10,Master!$D$2:$D$918,$C10,Master!$K$2:$K$918,">0"),"") | H10: =IF($F10=0,"Untouched",IF($G10="","No rating",IF($G10<=3,"Weak","Solid")))
B11: 02. Arrays & Two Pointers | C11: Frequency scan | D11: =COUNTIFS(Master!$C$2:$C$918,$B11,Master!$D$2:$D$918,$C11) | E11: =COUNTIFS(Master!$C$2:$C$918,$B11,Master!$D$2:$D$918,$C11,Master!$G$2:$G$918,"Core") | F11: =COUNTIFS(Master!$C$2:$C$918,$B11,Master!$D$2:$D$918,$C11,Master!$J$2:$J$918,"Solved")+COUNTIFS(Master!$C$2:$C$918,$B11,Master!$D$2:$D$918,$C11,Master!$J$2:$J$918,"Mastered") | G11: =IFERROR(AVERAGEIFS(Master!$K$2:$K$918,Master!$C$2:$C$918,$B11,Master!$D$2:$D$918,$C11,Master!$K$2:$K$918,">0"),"") | H11: =IF($F11=0,"Untouched",IF($G11="","No rating",IF($G11<=3,"Weak","Solid")))
B12: 02. Arrays & Two Pointers | C12: Voting / counting | D12: =COUNTIFS(Master!$C$2:$C$918,$B12,Master!$D$2:$D$918,$C12) | E12: =COUNTIFS(Master!$C$2:$C$918,$B12,Master!$D$2:$D$918,$C12,Master!$G$2:$G$918,"Core") | F12: =COUNTIFS(Master!$C$2:$C$918,$B12,Master!$D$2:$D$918,$C12,Master!$J$2:$J$918,"Solved")+COUNTIFS(Master!$C$2:$C$918,$B12,Master!$D$2:$D$918,$C12,Master!$J$2:$J$918,"Mastered") | G12: =IFERROR(AVERAGEIFS(Master!$K$2:$K$918,Master!$C$2:$C$918,$B12,Master!$D$2:$D$918,$C12,Master!$K$2:$K$918,">0"),"") | H12: =IF($F12=0,"Untouched",IF($G12="","No rating",IF($G12<=3,"Weak","Solid")))
B13: 02. Arrays & Two Pointers | C13: Rearrangement | D13: =COUNTIFS(Master!$C$2:$C$918,$B13,Master!$D$2:$D$918,$C13) | E13: =COUNTIFS(Master!$C$2:$C$918,$B13,Master!$D$2:$D$918,$C13,Master!$G$2:$G$918,"Core") | F13: =COUNTIFS(Master!$C$2:$C$918,$B13,Master!$D$2:$D$918,$C13,Master!$J$2:$J$918,"Solved")+COUNTIFS(Master!$C$2:$C$918,$B13,Master!$D$2:$D$918,$C13,Master!$J$2:$J$918,"Mastered") | G13: =IFERROR(AVERAGEIFS(Master!$K$2:$K$918,Master!$C$2:$C$918,$B13,Master!$D$2:$D$918,$C13,Master!$K$2:$K$918,">0"),"") | H13: =IF($F13=0,"Untouched",IF($G13="","No rating",IF($G13<=3,"Weak","Solid")))
B14: 02. Arrays & Two Pointers | C14: K-Sum | D14: =COUNTIFS(Master!$C$2:$C$918,$B14,Master!$D$2:$D$918,$C14) | E14: =COUNTIFS(Master!$C$2:$C$918,$B14,Master!$D$2:$D$918,$C14,Master!$G$2:$G$918,"Core") | F14: =COUNTIFS(Master!$C$2:$C$918,$B14,Master!$D$2:$D$918,$C14,Master!$J$2:$J$918,"Solved")+COUNTIFS(Master!$C$2:$C$918,$B14,Master!$D$2:$D$918,$C14,Master!$J$2:$J$918,"Mastered") | G14: =IFERROR(AVERAGEIFS(Master!$K$2:$K$918,Master!$C$2:$C$918,$B14,Master!$D$2:$D$918,$C14,Master!$K$2:$K$918,">0"),"") | H14: =IF($F14=0,"Untouched",IF($G14="","No rating",IF($G14<=3,"Weak","Solid")))
B15: 03. Sorting & Cyclic Sort | C15: Custom comparator | D15: =COUNTIFS(Master!$C$2:$C$918,$B15,Master!$D$2:$D$918,$C15) | E15: =COUNTIFS(Master!$C$2:$C$918,$B15,Master!$D$2:$D$918,$C15,Master!$G$2:$G$918,"Core") | F15: =COUNTIFS(Master!$C$2:$C$918,$B15,Master!$D$2:$D$918,$C15,Master!$J$2:$J$918,"Solved")+COUNTIFS(Master!$C$2:$C$918,$B15,Master!$D$2:$D$918,$C15,Master!$J$2:$J$918,"Mastered") | G15: =IFERROR(AVERAGEIFS(Master!$K$2:$K$918,Master!$C$2:$C$918,$B15,Master!$D$2:$D$918,$C15,Master!$K$2:$K$918,">0"),"") | H15: =IF($F15=0,"Untouched",IF($G15="","No rating",IF($G15<=3,"Weak","Solid")))
B16: 03. Sorting & Cyclic Sort | C16: Counting sort | D16: =COUNTIFS(Master!$C$2:$C$918,$B16,Master!$D$2:$D$918,$C16) | E16: =COUNTIFS(Master!$C$2:$C$918,$B16,Master!$D$2:$D$918,$C16,Master!$G$2:$G$918,"Core") | F16: =COUNTIFS(Master!$C$2:$C$918,$B16,Master!$D$2:$D$918,$C16,Master!$J$2:$J$918,"Solved")+COUNTIFS(Master!$C$2:$C$918,$B16,Master!$D$2:$D$918,$C16,Master!$J$2:$J$918,"Mastered") | G16: =IFERROR(AVERAGEIFS(Master!$K$2:$K$918,Master!$C$2:$C$918,$B16,Master!$D$2:$D$918,$C16,Master!$K$2:$K$918,">0"),"") | H16: =IF($F16=0,"Untouched",IF($G16="","No rating",IF($G16<=3,"Weak","Solid")))
B17: 03. Sorting & Cyclic Sort | C17: Cyclic sort | D17: =COUNTIFS(Master!$C$2:$C$918,$B17,Master!$D$2:$D$918,$C17) | E17: =COUNTIFS(Master!$C$2:$C$918,$B17,Master!$D$2:$D$918,$C17,Master!$G$2:$G$918,"Core") | F17: =COUNTIFS(Master!$C$2:$C$918,$B17,Master!$D$2:$D$918,$C17,Master!$J$2:$J$918,"Solved")+COUNTIFS(Master!$C$2:$C$918,$B17,Master!$D$2:$D$918,$C17,Master!$J$2:$J$918,"Mastered") | G17: =IFERROR(AVERAGEIFS(Master!$K$2:$K$918,Master!$C$2:$C$918,$B17,Master!$D$2:$D$918,$C17,Master!$K$2:$K$918,">0"),"") | H17: =IF($F17=0,"Untouched",IF($G17="","No rating",IF($G17<=3,"Weak","Solid")))
... B177: 21. Dynamic Programming | C177: Bitmask DP | D177: =COUNTIFS(Master!$C$2:$C$918,$B177,Master!$D$2:$D$918,$C177) | E177: =COUNTIFS(Master!$C$2:$C$918,$B177,Master!$D$2:$D$918,$C177,Master!$G$2:$G$918,"Core") | F177: =COUNTIFS(Master!$C$2:$C$918,$B177,Master!$D$2:$D$918,$C177,Master!$J$2:$J$918,"Solved")+COUNTIFS(Master!$C$2:$C$918,$B177,Master!$D$2:$D$918,$C177,Master!$J$2:$J$918,"Mastered") | G177: =IFERROR(AVERAGEIFS(Master!$K$2:$K$918,Master!$C$2:$C$918,$B177,Master!$D$2:$D$918,$C177,Master!$K$2:$K$918,">0"),"") | H177: =IF($F177=0,"Untouched",IF($G177="","No rating",IF($G177<=3,"Weak","Solid")))

Sheet Pattern Coverage
A1: Topic | B1: Pattern | C1: Core | D1: Depth | E1: Stretch
A2: 01. Basics & Recursion | B2: Recursion warm-up | C2: 10 | D2: 0 | E2: 0
A3: 01. Basics & Recursion | B3: Divide & Conquer | C3: 4 | D3: 0 | E3: 0
A4: 02. Arrays & Two Pointers | B4: Basics | C4: 3 | D4: 0 | E4: 0
A5: 02. Arrays & Two Pointers | B5: Two pointers | C5: 4 | D5: 10 | E5: 1
A6: 02. Arrays & Two Pointers | B6: Dutch National Flag | C6: 2 | D6: 2 | E6: 0
A7: 02. Arrays & Two Pointers | B7: Frequency scan | C7: 2 | D7: 0 | E7: 0
A8: 02. Arrays & Two Pointers | B8: Voting / counting | C8: 2 | D8: 0 | E8: 0
A9: 02. Arrays & Two Pointers | B9: Rearrangement | C9: 2 | D9: 3 | E9: 0
A10: 02. Arrays & Two Pointers | B10: K-Sum | C10: 3 | D10: 2 | E10: 0
A11: 03. Sorting & Cyclic Sort | B11: Custom comparator | C11: 3 | D11: 2 | E11: 0
A12: 03. Sorting & Cyclic Sort | B12: Counting sort | C12: 4 | D12: 1 | E12: 0
A13: 03. Sorting & Cyclic Sort | B13: Cyclic sort | C13: 2 | D13: 3 | E13: 1
... A173: 21. Dynamic Programming | B173: Bitmask DP | C173: 0 | D173: 0 | E173: 5
